<sdf version='1.7'>
  <world name='default'>
    <light name='sun' type='directional'>
      <cast_shadows>1</cast_shadows>
      <pose>0 0 10 0 -0 0</pose>
      <diffuse>0.8 0.8 0.8 1</diffuse>
      <specular>0.2 0.2 0.2 1</specular>
      <attenuation>
        <range>1000</range>
        <constant>0.9</constant>
        <linear>0.01</linear>
        <quadratic>0.001</quadratic>
      </attenuation>
      <direction>-0.5 0.1 -0.9</direction>
      <spot>
        <inner_angle>0</inner_angle>
        <outer_angle>0</outer_angle>
        <falloff>0</falloff>
      </spot>
    </light>
    <model name='ground_plane'>
      <static>1</static>
      <link name='link'>
        <collision name='collision'>
          <geometry>
            <plane>
              <normal>0 0 1</normal>
              <size>100 100</size>
            </plane>
          </geometry>
          <surface>
            <contact>
              <collide_bitmask>65535</collide_bitmask>
              <ode/>
            </contact>
            <friction>
              <ode>
                <mu>100</mu>
                <mu2>50</mu2>
              </ode>
              <torsional>
                <ode/>
              </torsional>
            </friction>
            <bounce/>
          </surface>
          <max_contacts>10</max_contacts>
        </collision>
        <visual name='visual'>
          <cast_shadows>0</cast_shadows>
          <geometry>
            <plane>
              <normal>0 0 1</normal>
              <size>100 100</size>
            </plane>
          </geometry>
          <material>
            <script>
              <uri>file://media/materials/scripts/gazebo.material</uri>
              <name>Gazebo/Grey</name>
            </script>
          </material>
        </visual>
        <self_collide>0</self_collide>
        <enable_wind>0</enable_wind>
        <kinematic>0</kinematic>
      </link>
    </model>
    <gravity>0 0 -9.8</gravity>
    <magnetic_field>6e-06 2.3e-05 -4.2e-05</magnetic_field>
    <atmosphere type='adiabatic'/>
    <physics name='default_physics' default='0' type='ode'>
      <max_step_size>0.001</max_step_size>
      <real_time_factor>1</real_time_factor>
      <real_time_update_rate>1000</real_time_update_rate>
    </physics>
    <scene>
      <ambient>0.4 0.4 0.4 1</ambient>
      <background>0.7 0.7 0.7 1</background>
      <shadows>1</shadows>
    </scene>
    <audio>
      <device>default</device>
    </audio>
    <wind/>
    <spherical_coordinates>
      <surface_model>EARTH_WGS84</surface_model>
      <latitude_deg>0</latitude_deg>
      <longitude_deg>0</longitude_deg>
      <elevation>0</elevation>
      <heading_deg>0</heading_deg>
    </spherical_coordinates>
    <state world_name='default'>
      <sim_time>2356 469000000</sim_time>
      <real_time>225 523689929</real_time>
      <wall_time>1670199752 828998537</wall_time>
      <iterations>92540</iterations>
      <model name='ground_plane'>
        <pose>0 0 0 0 -0 0</pose>
        <scale>1 1 1</scale>
        <link name='link'>
          <pose>0 0 0 0 -0 0</pose>
          <velocity>0 0 0 0 -0 0</velocity>
          <acceleration>0 0 0 0 -0 0</acceleration>
          <wrench>0 0 0 0 -0 0</wrench>
        </link>
      </model>
      <model name='my_robot'>
        <pose>0.047141 0.017921 -0.000237 3.1e-05 0.000689 -0.071876</pose>
        <scale>1 1 1</scale>
        <link name='dummy_link'>
          <pose>0.047141 0.017921 -0.000237 3.1e-05 0.000689 -0.071876</pose>
          <velocity>0.000403 0.000918 -0.00365 0.003849 -1.6e-05 -0.000446</velocity>
          <acceleration>-0.042896 0.190023 -2.09741 -3.10918 0.833243 -0.096591</acceleration>
          <wrench>-2.3045 10.2087 -112.68 0 -0 0</wrench>
        </link>
        <link name='forearm_link'>
          <pose>-0.165608 0.069215 0.12444 -3.14093 1.44912 2.97946</pose>
          <velocity>0.0005 0.001161 -0.003216 -0.001449 -0.006452 -0.006624</velocity>
          <acceleration>-0.70676 0.384058 -0.510842 -0.458666 -0.699743 2.78512</acceleration>
          <wrench>-1.60788 0.873733 -1.16217 0 -0 0</wrench>
        </link>
        <link name='left_front_wheel'>
          <pose>0.315353 0.203125 0.326119 -3.14158 0.000704 -0.058123</pose>
          <velocity>-0.001535 -0.00075 0.002643 0.001202 0.005374 0.11288</velocity>
          <acceleration>-9.46664 -1.63287 9.86511 1.63808 0.286334 2.31477</acceleration>
          <wrench>-4.50883 -0.777713 4.69861 0 -0 0</wrench>
        </link>
        <link name='left_rear_wheel'>
          <pose>-0.194213 0.201722 0.101463 1.57077 -0.161154 -0.07186</pose>
          <velocity>0.000531 0.001175 -0.008176 0.017463 -0.000685 -0.003683</velocity>
          <acceleration>0.441611 0.923101 -12.9838 -2.05859 -0.901731 -1.18847</acceleration>
          <wrench>0.25317 0.529202 -7.44343 0 -0 0</wrench>
        </link>
        <link name='left_roll'>
          <pose>0.312981 0.165198 0.101156 1.57079 0.006157 -0.058114</pose>
          <velocity>-0.000575 -0.001268 0.010862 -0.002098 -0.094696 0.118431</velocity>
          <acceleration>-7.18348 -3.54987 25.3607 0.691855 -1.05624 2.46541</acceleration>
          <wrench>-4.1182 -2.03509 14.539 0 -0 0</wrench>
        </link>
        <link name='right_front_wheel'>
          <pose>0.286056 -0.203818 0.326105 3.14157 0.000701 -0.159504</pose>
          <velocity>0.000963 -0.001139 -0.010414 -0.002456 -0.001768 0.012051</velocity>
          <acceleration>-3.20523 -0.83928 -12.912 -2.95138 1.00242 2.2479</acceleration>
          <wrench>-1.52661 -0.399738 -6.14979 0 -0 0</wrench>
        </link>
        <link name='right_rear_wheel'>
          <pose>-0.218056 -0.129417 0.101449 -1.57079 -0.184281 -0.071882</pose>
          <velocity>0.00045 0.001112 0.001136 -0.011341 0.003149 -0.001561</velocity>
          <acceleration>0.775775 1.36573 5.04519 -1.68392 -0.678671 2.19916</acceleration>
          <wrench>0.444742 0.782958 2.89234 0 -0 0</wrench>
        </link>
        <link name='right_roll'>
          <pose>0.291932 -0.166276 0.101138 1.57082 0.034214 2.98209</pose>
          <velocity>0.001674 -0.002245 -0.01891 0.011353 0.072842 0.012234</velocity>
          <acceleration>-5.28742 -1.54274 -29.9614 -2.61648 -0.589475 3.10106</acceleration>
          <wrench>-3.03121 -0.884435 -17.1765 0 -0 0</wrench>
        </link>
        <link name='shoulder_link'>
          <pose>0.047476 0.017882 0.488921 -8.1e-05 0.000689 -0.162788</pose>
          <velocity>0.000393 -0.000968 -0.00367 0.001596 0.00036 -0.006483</velocity>
          <acceleration>-0.872149 -0.162611 -2.09159 0.510674 1.30665 -0.643204</acceleration>
          <wrench>-3.22695 -0.60166 -7.73887 0 -0 0</wrench>
        </link>
        <link name='upper_arm_link'>
          <pose>0.069489 0.151937 0.488912 -3.1415 -0.540206 2.97876</pose>
          <velocity>0.001242 -0.00112 -0.00317 0.001793 0.000592 -0.00699</velocity>
          <acceleration>-0.656197 0.29841 -1.56312 0.100304 -0.523353 1.8337</acceleration>
          <wrench>-5.50746 2.50455 -13.1193 0 -0 0</wrench>
        </link>
        <link name='vacuum_effector'>
          <pose>0.239764 0.176092 0.162911 3.11558 -0.118962 -3.08788</pose>
          <velocity>0.001205 -0.001608 -0.00058 0.000299 -0.001106 -0.004408</velocity>
          <acceleration>-0.560104 0.28307 0.03238 -0.728549 -0.759604 -0.054132</acceleration>
          <wrench>-5.6e-05 2.8e-05 3e-06 0 -0 0</wrench>
        </link>
        <link name='wrist_1_link'>
          <pose>0.218593 0.00611 0.076829 -8.2e-05 0.121741 -0.162795</pose>
          <velocity>0.000387 -0.001455 -0.000648 1.7e-05 -0.001534 -0.006627</velocity>
          <acceleration>-0.651543 0.230538 0.168033 -0.816433 0.132389 -0.63532</acceleration>
          <wrench>-0.794231 0.281026 0.204832 0 -0 0</wrench>
        </link>
        <link name='wrist_2_link'>
          <pose>0.233666 0.09788 0.076821 0.02601 0.118943 0.053709</pose>
          <velocity>0.000998 -0.001553 -0.000617 0.000301 -0.001583 -0.004418</velocity>
          <acceleration>-0.585318 0.219211 0.091989 -0.819766 0.130164 0.020324</acceleration>
          <wrench>-0.713502 0.267219 0.112134 0 -0 0</wrench>
        </link>
        <link name='wrist_3_link'>
          <pose>0.245009 0.096025 0.170771 3.11558 -0.118962 -3.08788</pose>
          <velocity>0.000842 -0.001633 -0.000599 0.000289 -0.001107 -0.004406</velocity>
          <acceleration>-0.571715 0.291073 0.093443 -0.736913 -0.762126 -0.006925</acceleration>
          <wrench>-0.107425 0.054693 0.017558 0 -0 0</wrench>
        </link>
      </model>
      <model name='table'>
        <pose>1.8e-05 0.659275 0 0 -0 0</pose>
        <scale>1 1 1</scale>
        <link name='link'>
          <pose>1.8e-05 0.659275 0 0 -0 0</pose>
          <velocity>0 0 0 0 -0 0</velocity>
          <acceleration>0 0 0 0 -0 0</acceleration>
          <wrench>0 0 0 0 -0 0</wrench>
        </link>
      </model>
      <model name='table_clone'>
        <pose>3.18521 0.717754 0 0 -0 0</pose>
        <scale>1 1 1</scale>
        <link name='link'>
          <pose>3.18521 0.717754 0 0 -0 0</pose>
          <velocity>0 0 0 0 -0 0</velocity>
          <acceleration>0 0 0 0 -0 0</acceleration>
          <wrench>0 0 0 0 -0 0</wrench>
        </link>
      </model>
      <model name='table_clone_0'>
        <pose>0.013705 -1.85505 0 0 -0 0</pose>
        <scale>1 1 1</scale>
        <link name='link'>
          <pose>0.013705 -1.85505 0 0 -0 0</pose>
          <velocity>0 0 0 0 -0 0</velocity>
          <acceleration>0 0 0 0 -0 0</acceleration>
          <wrench>0 0 0 0 -0 0</wrench>
        </link>
      </model>
      <model name='table_clone_clone'>
        <pose>3.20756 -1.90712 0 0 -0 0</pose>
        <scale>1 1 1</scale>
        <link name='link'>
          <pose>3.20756 -1.90712 0 0 -0 0</pose>
          <velocity>0 0 0 0 -0 0</velocity>
          <acceleration>0 0 0 0 -0 0</acceleration>
          <wrench>0 0 0 0 -0 0</wrench>
        </link>
      </model>
      <model name='unit_box_blue'>
        <pose>0.3 0.5 0.38125 0 -0 1e-06</pose>
        <scale>1 1 1</scale>
        <link name='link'>
          <pose>0.3 0.5 0.38125 0 -0 1e-06</pose>
          <velocity>0 0 0 0 -0 0</velocity>
          <acceleration>0 -0 0 0 -0 0</acceleration>
          <wrench>0 -0 0 0 -0 0</wrench>
        </link>
      </model>
      <model name='unit_box_blue_clone'>
        <pose>3.29261 0.58342 0.38125 0 -0 1e-06</pose>
        <scale>1 1 1</scale>
        <link name='link'>
          <pose>3.29261 0.58342 0.38125 0 -0 1e-06</pose>
          <velocity>0 0 0 0 -0 0</velocity>
          <acceleration>-0 0 0 0 -0 0</acceleration>
          <wrench>-0 0 0 0 -0 0</wrench>
        </link>
      </model>
      <model name='unit_box_blue_clone_0'>
        <pose>0.437495 -1.75176 0.38125 0 -0 1e-06</pose>
        <scale>1 1 1</scale>
        <link name='link'>
          <pose>0.437495 -1.75176 0.38125 0 -0 1e-06</pose>
          <velocity>0 0 0 0 -0 0</velocity>
          <acceleration>-0 0 0 -0 -0 -0</acceleration>
          <wrench>-0 0 0 0 -0 0</wrench>
        </link>
      </model>
      <model name='unit_box_blue_clone_1'>
        <pose>3.38684 -1.77494 0.38125 0 -0 1e-06</pose>
        <scale>1 1 1</scale>
        <link name='link'>
          <pose>3.38684 -1.77494 0.38125 0 -0 1e-06</pose>
          <velocity>0 0 0 0 -0 0</velocity>
          <acceleration>-0 0 0 -0 -0 -0</acceleration>
          <wrench>-0 0 0 0 -0 0</wrench>
        </link>
      </model>
      <light name='sun'>
        <pose>0 0 10 0 -0 0</pose>
      </light>
    </state>
    <gui fullscreen='0'>
      <camera name='user_camera'>
        <pose>16.3564 -0.05642 11.4693 0 0.473798 2.82961</pose>
        <view_controller>orbit</view_controller>
        <projection_type>perspective</projection_type>
      </camera>
    </gui>
    <model name='table'>
      <static>1</static>
      <link name='link'>
        <collision name='surface'>
          <pose>0 0.075 0 0 -0 0</pose>
          <geometry>
            <box>
              <size>2.1 0.8 0.7</size>
            </box>
          </geometry>
          <surface>
            <friction>
              <ode>
                <mu>0.6</mu>
                <mu2>0.6</mu2>
              </ode>
              <torsional>
                <ode/>
              </torsional>
            </friction>
            <contact>
              <ode/>
            </contact>
            <bounce/>
          </surface>
          <max_contacts>10</max_contacts>
        </collision>
        <visual name='visual1'>
          <pose>0 0.075 0 0 -0 0</pose>
          <geometry>
            <box>
              <size>2.1 0.8 0.7</size>
            </box>
          </geometry>
          <material>
            <script>
              <uri>file://media/materials/scripts/gazebo.material</uri>
              <name>Gazebo/Wood</name>
            </script>
          </material>
        </visual>
        <self_collide>0</self_collide>
        <enable_wind>0</enable_wind>
        <kinematic>0</kinematic>
      </link>
      <pose>0.270759 1.80105 0 0 -0 0</pose>
    </model>
    <model name='unit_box_blue'>
      <link name='link'>
        <inertial>
          <mass>0.05</mass>
          <inertia>
            <ixx>5.763e-05</ixx>
            <ixy>0</ixy>
            <ixz>0</ixz>
            <iyy>6.331e-05</iyy>
            <iyz>0</iyz>
            <izz>6.119e-05</izz>
          </inertia>
          <pose>0 0 0 0 -0 0</pose>
        </inertial>
        <self_collide>0</self_collide>
        <enable_wind>0</enable_wind>
        <kinematic>0</kinematic>
        <pose>0 0 0 0 -0 0</pose>
        <gravity>1</gravity>
        <visual name='visual'>
          <geometry>
            <box>
              <size>0.1 0.1 0.0625</size>
            </box>
          </geometry>
          <material>
            <script>
              <name>Gazebo/Grey</name>
              <uri>file://media/materials/scripts/gazebo.material</uri>
            </script>
            <ambient>0 0 1 1</ambient>
            <shader type='vertex'>
              <normal_map>__default__</normal_map>
            </shader>
            <diffuse>0.7 0.7 0.7 1</diffuse>
            <specular>0.01 0.01 0.01 1</specular>
            <emissive>0 0 0 1</emissive>
          </material>
          <pose>0 0 0 0 -0 0</pose>
          <transparency>0</transparency>
          <cast_shadows>1</cast_shadows>
        </visual>
        <collision name='collision'>
          <laser_retro>0</laser_retro>
          <max_contacts>10</max_contacts>
          <pose>0 0 0 0 -0 0</pose>
          <geometry>
            <box>
              <size>0.1 0.1 0.0625</size>
            </box>
          </geometry>
          <surface>
            <friction>
              <ode>
                <mu>5</mu>
                <mu2>5</mu2>
                <fdir1>0 0 0</fdir1>
                <slip1>0</slip1>
                <slip2>0</slip2>
              </ode>
              <torsional>
                <coefficient>1</coefficient>
                <patch_radius>0</patch_radius>
                <surface_radius>0</surface_radius>
                <use_patch_radius>1</use_patch_radius>
                <ode>
                  <slip>0</slip>
                </ode>
              </torsional>
            </friction>
            <bounce>
              <restitution_coefficient>0</restitution_coefficient>
              <threshold>1e+06</threshold>
            </bounce>
            <contact>
              <collide_without_contact>0</collide_without_contact>
              <collide_without_contact_bitmask>1</collide_without_contact_bitmask>
              <collide_bitmask>1</collide_bitmask>
              <ode>
                <soft_cfm>0</soft_cfm>
                <soft_erp>0.2</soft_erp>
                <kp>1e+13</kp>
                <kd>1</kd>
                <max_vel>0.01</max_vel>
                <min_depth>0</min_depth>
              </ode>
              <bullet>
                <split_impulse>1</split_impulse>
                <split_impulse_penetration_threshold>-0.01</split_impulse_penetration_threshold>
                <soft_cfm>0</soft_cfm>
                <soft_erp>0.2</soft_erp>
                <kp>1e+13</kp>
                <kd>1</kd>
              </bullet>
            </contact>
          </surface>
        </collision>
      </link>
      <static>0</static>
      <allow_auto_disable>1</allow_auto_disable>
      <pose>0.299999 0.5 1.04493 -1e-06 -2e-05 1e-06</pose>
    </model>
    <model name='my_robot'>
      <link name='dummy_link'>
        <inertial>
          <pose>-0.004504 -0 0.329684 0 -0 0</pose>
          <mass>53.7232</mass>
          <inertia>
            <ixx>1.11636</ixx>
            <ixy>-3.3527e-09</ixy>
            <ixz>-0.00136863</ixz>
            <iyy>3.85985</iyy>
            <iyz>4.26883e-18</iyz>
            <izz>4.84001</izz>
          </inertia>
        </inertial>
        <collision name='dummy_link_fixed_joint_lump__bat_collision'>
          <pose>0 0 0 0 -0 0</pose>
          <geometry>
            <mesh>
              <scale>1 1 1</scale>
              <uri>/home/shivam/catkin_ws2/src/batbat/meshes/bat.STL</uri>
            </mesh>
          </geometry>
          <max_contacts>10</max_contacts>
          <surface>
            <contact>
              <ode/>
            </contact>
            <bounce/>
            <friction>
              <torsional>
                <ode/>
              </torsional>
              <ode/>
            </friction>
          </surface>
        </collision>
        <collision name='dummy_link_fixed_joint_lump__base_link_collision_1'>
          <pose>0 0 0.4 0 -0 0</pose>
          <geometry>
            <mesh>
              <scale>1 1 1</scale>
              <uri>/home/shivam/catkin_ws2/src/ur_description/meshes/ur5/collision/base.stl</uri>
            </mesh>
          </geometry>
          <max_contacts>10</max_contacts>
          <surface>
            <contact>
              <ode/>
            </contact>
            <bounce/>
            <friction>
              <torsional>
                <ode/>
              </torsional>
              <ode/>
            </friction>
          </surface>
        </collision>
        <visual name='dummy_link_fixed_joint_lump__bat_visual'>
          <pose>0 0 0 0 -0 0</pose>
          <geometry>
            <mesh>
              <scale>1 1 1</scale>
              <uri>/home/shivam/catkin_ws2/src/batbat/meshes/bat.STL</uri>
            </mesh>
          </geometry>
        </visual>
        <visual name='dummy_link_fixed_joint_lump__base_link_visual_1'>
          <pose>0 0 0.4 0 -0 0</pose>
          <geometry>
            <mesh>
              <scale>1 1 1</scale>
              <uri>/home/shivam/catkin_ws2/src/ur_description/meshes/ur5/visual/base.dae</uri>
            </mesh>
          </geometry>
        </visual>
        <self_collide>0</self_collide>
        <enable_wind>0</enable_wind>
        <kinematic>0</kinematic>
      </link>
      <joint name='shoulder_sweep_joint' type='revolute'>
        <pose relative_to='dummy_link'>0 0 0.489159 0 -0 0</pose>
        <parent>dummy_link</parent>
        <child>shoulder_link</child>
        <axis>
          <xyz>0 0 1</xyz>
          <limit>
            <lower>-3.14159</lower>
            <upper>3.14159</upper>
            <effort>150</effort>
            <velocity>3.15</velocity>
          </limit>
          <dynamics>
            <damping>0</damping>
            <friction>0</friction>
            <spring_reference>0</spring_reference>
            <spring_stiffness>0</spring_stiffness>
          </dynamics>
        </axis>
      </joint>
      <link name='shoulder_link'>
        <pose relative_to='shoulder_sweep_joint'>0 0 0 0 -0 0</pose>
        <inertial>
          <pose>0 0 0 0 -0 0</pose>
          <mass>3.7</mass>
          <inertia>
            <ixx>0.0102675</ixx>
            <ixy>0</ixy>
            <ixz>0</ixz>
            <iyy>0.0102675</iyy>
            <iyz>0</iyz>
            <izz>0.00666</izz>
          </inertia>
        </inertial>
        <collision name='shoulder_link_collision'>
          <pose>0 0 0 0 -0 0</pose>
          <geometry>
            <mesh>
              <scale>1 1 1</scale>
              <uri>/home/shivam/catkin_ws2/src/ur_description/meshes/ur5/collision/shoulder.stl</uri>
            </mesh>
          </geometry>
          <max_contacts>10</max_contacts>
          <surface>
            <contact>
              <ode/>
            </contact>
            <bounce/>
            <friction>
              <torsional>
                <ode/>
              </torsional>
              <ode/>
            </friction>
          </surface>
        </collision>
        <visual name='shoulder_link_visual'>
          <pose>0 0 0 0 -0 0</pose>
          <geometry>
            <mesh>
              <scale>1 1 1</scale>
              <uri>/home/shivam/catkin_ws2/src/ur_description/meshes/ur5/visual/shoulder.dae</uri>
            </mesh>
          </geometry>
        </visual>
        <self_collide>0</self_collide>
        <enable_wind>0</enable_wind>
        <kinematic>0</kinematic>
      </link>
      <joint name='shoulder_lift_joint' type='revolute'>
        <pose relative_to='shoulder_link'>0 0.13585 0 3.14159 1.57079 3.14159</pose>
        <parent>shoulder_link</parent>
        <child>upper_arm_link</child>
        <axis>
          <xyz>0 1 0</xyz>
          <limit>
            <lower>-3.14159</lower>
            <upper>3.14159</upper>
            <effort>150</effort>
            <velocity>3.15</velocity>
          </limit>
          <dynamics>
            <damping>0</damping>
            <friction>0</friction>
            <spring_reference>0</spring_reference>
            <spring_stiffness>0</spring_stiffness>
          </dynamics>
        </axis>
      </joint>
      <link name='upper_arm_link'>
        <pose relative_to='shoulder_lift_joint'>0 0 0 0 -0 0</pose>
        <inertial>
          <pose>0 0 0.28 0 -0 0</pose>
          <mass>8.393</mass>
          <inertia>
            <ixx>0.226891</ixx>
            <ixy>0</ixy>
            <ixz>0</ixz>
            <iyy>0.226891</iyy>
            <iyz>0</iyz>
            <izz>0.0151074</izz>
          </inertia>
        </inertial>
        <collision name='upper_arm_link_collision'>
          <pose>0 0 0 0 -0 0</pose>
          <geometry>
            <mesh>
              <scale>1 1 1</scale>
              <uri>/home/shivam/catkin_ws2/src/ur_description/meshes/ur5/collision/upperarm.stl</uri>
            </mesh>
          </geometry>
          <max_contacts>10</max_contacts>
          <surface>
            <contact>
              <ode/>
            </contact>
            <bounce/>
            <friction>
              <torsional>
                <ode/>
              </torsional>
              <ode/>
            </friction>
          </surface>
        </collision>
        <visual name='upper_arm_link_visual'>
          <pose>0 0 0 0 -0 0</pose>
          <geometry>
            <mesh>
              <scale>1 1 1</scale>
              <uri>/home/shivam/catkin_ws2/src/ur_description/meshes/ur5/visual/upperarm.dae</uri>
            </mesh>
          </geometry>
        </visual>
        <self_collide>0</self_collide>
        <enable_wind>0</enable_wind>
        <kinematic>0</kinematic>
      </link>
      <joint name='elbow_joint' type='revolute'>
        <pose relative_to='upper_arm_link'>0 -0.1197 0.425 0 -0 0</pose>
        <parent>upper_arm_link</parent>
        <child>forearm_link</child>
        <axis>
          <xyz>0 1 0</xyz>
          <limit>
            <lower>-3.14159</lower>
            <upper>3.14159</upper>
            <effort>150</effort>
            <velocity>3.15</velocity>
          </limit>
          <dynamics>
            <damping>0</damping>
            <friction>0</friction>
            <spring_reference>0</spring_reference>
            <spring_stiffness>0</spring_stiffness>
          </dynamics>
        </axis>
      </joint>
      <link name='forearm_link'>
        <pose relative_to='elbow_joint'>0 0 0 0 -0 0</pose>
        <inertial>
          <pose>0 0 0.25 0 -0 0</pose>
          <mass>2.275</mass>
          <inertia>
            <ixx>0.0494433</ixx>
            <ixy>0</ixy>
            <ixz>0</ixz>
            <iyy>0.0494433</iyy>
            <iyz>0</iyz>
            <izz>0.004095</izz>
          </inertia>
        </inertial>
        <collision name='forearm_link_collision'>
          <pose>0 0 0 0 -0 0</pose>
          <geometry>
            <mesh>
              <scale>1 1 1</scale>
              <uri>/home/shivam/catkin_ws2/src/ur_description/meshes/ur5/collision/forearm.stl</uri>
            </mesh>
          </geometry>
          <max_contacts>10</max_contacts>
          <surface>
            <contact>
              <ode/>
            </contact>
            <bounce/>
            <friction>
              <torsional>
                <ode/>
              </torsional>
              <ode/>
            </friction>
          </surface>
        </collision>
        <visual name='forearm_link_visual'>
          <pose>0 0 0 0 -0 0</pose>
          <geometry>
            <mesh>
              <scale>1 1 1</scale>
              <uri>/home/shivam/catkin_ws2/src/ur_description/meshes/ur5/visual/forearm.dae</uri>
            </mesh>
          </geometry>
        </visual>
        <self_collide>0</self_collide>
        <enable_wind>0</enable_wind>
        <kinematic>0</kinematic>
      </link>
      <joint name='wrist_pitch_joint' type='revolute'>
        <pose relative_to='forearm_link'>0 0 0.39225 3.14159 1.57079 3.14159</pose>
        <parent>forearm_link</parent>
        <child>wrist_1_link</child>
        <axis>
          <xyz>0 1 0</xyz>
          <limit>
            <lower>-3.14159</lower>
            <upper>3.14159</upper>
            <effort>28</effort>
            <velocity>3.2</velocity>
          </limit>
          <dynamics>
            <damping>0</damping>
            <friction>0</friction>
            <spring_reference>0</spring_reference>
            <spring_stiffness>0</spring_stiffness>
          </dynamics>
        </axis>
      </joint>
      <link name='wrist_1_link'>
        <pose relative_to='wrist_pitch_joint'>0 0 0 0 -0 0</pose>
        <inertial>
          <pose>0 0 0 0 -0 0</pose>
          <mass>1.219</mass>
          <inertia>
            <ixx>0.111173</ixx>
            <ixy>0</ixy>
            <ixz>0</ixz>
            <iyy>0.111173</iyy>
            <iyz>0</iyz>
            <izz>0.21942</izz>
          </inertia>
        </inertial>
        <collision name='wrist_1_link_collision'>
          <pose>0 0 0 0 -0 0</pose>
          <geometry>
            <mesh>
              <scale>1 1 1</scale>
              <uri>/home/shivam/catkin_ws2/src/ur_description/meshes/ur5/collision/wrist1.stl</uri>
            </mesh>
          </geometry>
          <max_contacts>10</max_contacts>
          <surface>
            <contact>
              <ode/>
            </contact>
            <bounce/>
            <friction>
              <torsional>
                <ode/>
              </torsional>
              <ode/>
            </friction>
          </surface>
        </collision>
        <visual name='wrist_1_link_visual'>
          <pose>0 0 0 0 -0 0</pose>
          <geometry>
            <mesh>
              <scale>1 1 1</scale>
              <uri>/home/shivam/catkin_ws2/src/ur_description/meshes/ur5/visual/wrist1.dae</uri>
            </mesh>
          </geometry>
        </visual>
        <self_collide>0</self_collide>
        <enable_wind>0</enable_wind>
        <kinematic>0</kinematic>
      </link>
      <joint name='wrist_roll_joint' type='revolute'>
        <pose relative_to='wrist_1_link'>0 0.093 0 0 -0 0</pose>
        <parent>wrist_1_link</parent>
        <child>wrist_2_link</child>
        <axis>
          <xyz>0 0 1</xyz>
          <limit>
            <lower>-3.14159</lower>
            <upper>3.14159</upper>
            <effort>28</effort>
            <velocity>3.2</velocity>
          </limit>
          <dynamics>
            <damping>0</damping>
            <friction>0</friction>
            <spring_reference>0</spring_reference>
            <spring_stiffness>0</spring_stiffness>
          </dynamics>
        </axis>
      </joint>
      <link name='wrist_2_link'>
        <pose relative_to='wrist_roll_joint'>0 0 0 0 -0 0</pose>
        <inertial>
          <pose>0 0 0 0 -0 0</pose>
          <mass>1.219</mass>
          <inertia>
            <ixx>0.111173</ixx>
            <ixy>0</ixy>
            <ixz>0</ixz>
            <iyy>0.111173</iyy>
            <iyz>0</iyz>
            <izz>0.21942</izz>
          </inertia>
        </inertial>
        <collision name='wrist_2_link_collision'>
          <pose>0 0 0 0 -0 0</pose>
          <geometry>
            <mesh>
              <scale>1 1 1</scale>
              <uri>/home/shivam/catkin_ws2/src/ur_description/meshes/ur5/collision/wrist2.stl</uri>
            </mesh>
          </geometry>
          <max_contacts>10</max_contacts>
          <surface>
            <contact>
              <ode/>
            </contact>
            <bounce/>
            <friction>
              <torsional>
                <ode/>
              </torsional>
              <ode/>
            </friction>
          </surface>
        </collision>
        <visual name='wrist_2_link_visual'>
          <pose>0 0 0 0 -0 0</pose>
          <geometry>
            <mesh>
              <scale>1 1 1</scale>
              <uri>/home/shivam/catkin_ws2/src/ur_description/meshes/ur5/visual/wrist2.dae</uri>
            </mesh>
          </geometry>
        </visual>
        <self_collide>0</self_collide>
        <enable_wind>0</enable_wind>
        <kinematic>0</kinematic>
      </link>
      <joint name='wrist_yaw_joint' type='revolute'>
        <pose relative_to='wrist_2_link'>0 0 0.09465 0 -0 0</pose>
        <parent>wrist_2_link</parent>
        <child>wrist_3_link</child>
        <axis>
          <xyz>0 1 0</xyz>
          <limit>
            <lower>-3.14159</lower>
            <upper>3.14159</upper>
            <effort>28</effort>
            <velocity>3.2</velocity>
          </limit>
          <dynamics>
            <damping>0</damping>
            <friction>0</friction>
            <spring_reference>0</spring_reference>
            <spring_stiffness>0</spring_stiffness>
          </dynamics>
        </axis>
      </joint>
      <link name='wrist_3_link'>
        <pose relative_to='wrist_yaw_joint'>0 0 0 0 -0 0</pose>
        <inertial>
          <pose>0 0 0 0 -0 0</pose>
          <mass>0.1879</mass>
          <inertia>
            <ixx>0.0171365</ixx>
            <ixy>0</ixy>
            <ixz>0</ixz>
            <iyy>0.0171365</iyy>
            <iyz>0</iyz>
            <izz>0.033822</izz>
          </inertia>
        </inertial>
        <collision name='wrist_3_link_collision'>
          <pose>0 0 0 0 -0 0</pose>
          <geometry>
            <mesh>
              <scale>1 1 1</scale>
              <uri>/home/shivam/catkin_ws2/src/ur_description/meshes/ur5/collision/wrist3.stl</uri>
            </mesh>
          </geometry>
          <max_contacts>10</max_contacts>
          <surface>
            <contact>
              <ode/>
            </contact>
            <bounce/>
            <friction>
              <torsional>
                <ode/>
              </torsional>
              <ode/>
            </friction>
          </surface>
        </collision>
        <collision name='wrist_3_link_fixed_joint_lump__ee_link_collision_1'>
          <pose>-0 0.0723 0 0 -0 1.5708</pose>
          <geometry>
            <box>
              <size>0.01 0.01 0.01</size>
            </box>
          </geometry>
          <max_contacts>10</max_contacts>
          <surface>
            <contact>
              <ode/>
            </contact>
            <bounce/>
            <friction>
              <torsional>
                <ode/>
              </torsional>
              <ode/>
            </friction>
          </surface>
        </collision>
        <visual name='wrist_3_link_visual'>
          <pose>0 0 0 0 -0 0</pose>
          <geometry>
            <mesh>
              <scale>1 1 1</scale>
              <uri>/home/shivam/catkin_ws2/src/ur_description/meshes/ur5/visual/wrist3.dae</uri>
            </mesh>
          </geometry>
        </visual>
        <self_collide>0</self_collide>
        <enable_wind>0</enable_wind>
        <kinematic>0</kinematic>
      </link>
      <joint name='left_end_joint' type='revolute'>
        <pose relative_to='wrist_3_link'>0 0.08 0.01 0 -0 0</pose>
        <parent>wrist_3_link</parent>
        <child>vacuum_effector</child>
        <axis>
          <xyz>1 0 0</xyz>
          <limit>
            <lower>0</lower>
            <upper>0</upper>
            <effort>30</effort>
            <velocity>1</velocity>
          </limit>
          <dynamics>
            <spring_reference>0</spring_reference>
            <spring_stiffness>0</spring_stiffness>
          </dynamics>
        </axis>
      </joint>
      <link name='vacuum_effector'>
        <pose relative_to='left_end_joint'>0 0 0 0 -0 0</pose>
        <inertial>
          <pose>0 0 0 0 -0 0</pose>
          <mass>0.0001</mass>
          <inertia>
            <ixx>1e-08</ixx>
            <ixy>0</ixy>
            <ixz>0</ixz>
            <iyy>1e-08</iyy>
            <iyz>0</iyz>
            <izz>1e-08</izz>
          </inertia>
        </inertial>
        <visual name='vacuum_effector_visual'>
          <pose>0 0 0 0 -0 0</pose>
          <geometry>
            <box>
              <size>0.05 0.02 0.05</size>
            </box>
          </geometry>
        </visual>
        <self_collide>0</self_collide>
        <enable_wind>0</enable_wind>
        <kinematic>0</kinematic>
      </link>
      <joint name='left_front_wheel_joint' type='revolute'>
        <pose relative_to='dummy_link'>0.254 0.204 0.3265 3.14159 -0 0</pose>
        <parent>dummy_link</parent>
        <child>left_front_wheel</child>
        <axis>
          <xyz>0 0 1</xyz>
          <limit>
            <lower>-3</lower>
            <upper>3</upper>
            <effort>10</effort>
            <velocity>100</velocity>
          </limit>
          <dynamics>
            <spring_reference>0</spring_reference>
            <spring_stiffness>0</spring_stiffness>
          </dynamics>
        </axis>
      </joint>
      <link name='left_front_wheel'>
        <pose relative_to='left_front_wheel_joint'>0 0 0 0 -0 0</pose>
        <inertial>
          <pose>-0 -0.03032 0.135652 0 -0 0</pose>
          <mass>0.476286</mass>
          <inertia>
            <ixx>0.00308338</ixx>
            <ixy>1.67635e-09</ixy>
            <ixz>-1.85092e-09</ixz>
            <iyy>0.00267628</iyy>
            <iyz>0.000153347</iyz>
            <izz>0.00050234</izz>
          </inertia>
        </inertial>
        <collision name='left_front_wheel_collision'>
          <pose>0 0 0 0 -0 0</pose>
          <geometry>
            <mesh>
              <scale>1 1 1</scale>
              <uri>/home/shivam/catkin_ws2/src/batbat/meshes/left_front_wheel.STL</uri>
            </mesh>
          </geometry>
          <max_contacts>10</max_contacts>
          <surface>
            <contact>
              <ode/>
            </contact>
            <bounce/>
            <friction>
              <torsional>
                <ode/>
              </torsional>
              <ode/>
            </friction>
          </surface>
        </collision>
        <visual name='left_front_wheel_visual'>
          <pose>0 0 0 0 -0 0</pose>
          <geometry>
            <mesh>
              <scale>1 1 1</scale>
              <uri>/home/shivam/catkin_ws2/src/batbat/meshes/left_front_wheel.STL</uri>
            </mesh>
          </geometry>
        </visual>
        <self_collide>0</self_collide>
        <enable_wind>0</enable_wind>
        <kinematic>0</kinematic>
      </link>
      <joint name='left_roll_joint' type='revolute'>
        <pose relative_to='left_front_wheel'>0 0.038 0.225 -1.5708 0 0</pose>
        <parent>left_front_wheel</parent>
        <child>left_roll</child>
        <axis>
          <xyz>0 0 -1</xyz>
          <limit>
            <lower>-1e+16</lower>
            <upper>1e+16</upper>
          </limit>
          <dynamics>
            <spring_reference>0</spring_reference>
            <spring_stiffness>0</spring_stiffness>
          </dynamics>
        </axis>
      </joint>
      <link name='left_roll'>
        <pose relative_to='left_roll_joint'>0 0 0 0 -0 0</pose>
        <inertial>
          <pose>-0 0 -0.0385 0 -0 0</pose>
          <mass>0.573287</mass>
          <inertia>
            <ixx>0.00239464</ixx>
            <ixy>2.38768e-20</ixy>
            <ixz>5.17032e-19</ixz>
            <iyy>0.00239464</iyy>
            <iyz>-2.92577e-19</iyz>
            <izz>0.00432457</izz>
          </inertia>
        </inertial>
        <collision name='left_roll_collision'>
          <pose>0 0 0 0 -0 0</pose>
          <geometry>
            <mesh>
              <scale>1 1 1</scale>
              <uri>/home/shivam/catkin_ws2/src/batbat/meshes/left_roll.STL</uri>
            </mesh>
          </geometry>
          <max_contacts>10</max_contacts>
          <surface>
            <contact>
              <ode/>
            </contact>
            <bounce/>
            <friction>
              <torsional>
                <ode/>
              </torsional>
              <ode/>
            </friction>
          </surface>
        </collision>
        <visual name='left_roll_visual'>
          <pose>0 0 0 0 -0 0</pose>
          <geometry>
            <mesh>
              <scale>1 1 1</scale>
              <uri>/home/shivam/catkin_ws2/src/batbat/meshes/left_roll.STL</uri>
            </mesh>
          </geometry>
        </visual>
        <self_collide>0</self_collide>
        <enable_wind>0</enable_wind>
        <kinematic>0</kinematic>
      </link>
      <joint name='left_rear_wheel_joint' type='revolute'>
        <pose relative_to='dummy_link'>-0.254 0.166 0.1015 1.5708 -0 0</pose>
        <parent>dummy_link</parent>
        <child>left_rear_wheel</child>
        <axis>
          <xyz>0 0 -1</xyz>
          <limit>
            <lower>-1e+16</lower>
            <upper>1e+16</upper>
          </limit>
          <dynamics>
            <spring_reference>0</spring_reference>
            <spring_stiffness>0</spring_stiffness>
          </dynamics>
        </axis>
      </joint>
      <link name='left_rear_wheel'>
        <pose relative_to='left_rear_wheel_joint'>0 0 0 0 -0 0</pose>
        <inertial>
          <pose>0 -0 -0.0385 0 -0 0</pose>
          <mass>0.573287</mass>
          <inertia>
            <ixx>0.00239464</ixx>
            <ixy>-7.27413e-19</ixy>
            <ixz>5.4595e-19</ixz>
            <iyy>0.00239464</iyy>
            <iyz>-2.06639e-19</iyz>
            <izz>0.00432457</izz>
          </inertia>
        </inertial>
        <collision name='left_rear_wheel_collision'>
          <pose>0 0 0 0 -0 0</pose>
          <geometry>
            <mesh>
              <scale>1 1 1</scale>
              <uri>/home/shivam/catkin_ws2/src/batbat/meshes/left_rear_wheel.STL</uri>
            </mesh>
          </geometry>
          <max_contacts>10</max_contacts>
          <surface>
            <contact>
              <ode/>
            </contact>
            <bounce/>
            <friction>
              <torsional>
                <ode/>
              </torsional>
              <ode/>
            </friction>
          </surface>
        </collision>
        <visual name='left_rear_wheel_visual'>
          <pose>0 0 0 0 -0 0</pose>
          <geometry>
            <mesh>
              <scale>1 1 1</scale>
              <uri>/home/shivam/catkin_ws2/src/batbat/meshes/left_rear_wheel.STL</uri>
            </mesh>
          </geometry>
        </visual>
        <self_collide>0</self_collide>
        <enable_wind>0</enable_wind>
        <kinematic>0</kinematic>
      </link>
      <joint name='right_front_wheel_joint' type='revolute'>
        <pose relative_to='dummy_link'>0.254 -0.204 0.3265 3.14159 -0 0</pose>
        <parent>dummy_link</parent>
        <child>right_front_wheel</child>
        <axis>
          <xyz>0 0 1</xyz>
          <limit>
            <lower>-3</lower>
            <upper>3</upper>
            <effort>10</effort>
            <velocity>100</velocity>
          </limit>
          <dynamics>
            <spring_reference>0</spring_reference>
            <spring_stiffness>0</spring_stiffness>
          </dynamics>
        </axis>
      </joint>
      <link name='right_front_wheel'>
        <pose relative_to='right_front_wheel_joint'>0 0 0 0 -0 0</pose>
        <inertial>
          <pose>0 0.03032 0.135652 0 -0 0</pose>
          <mass>0.476286</mass>
          <inertia>
            <ixx>0.00308338</ixx>
            <ixy>1.67635e-09</ixy>
            <ixz>1.85092e-09</ixz>
            <iyy>0.00267628</iyy>
            <iyz>-0.000153347</iyz>
            <izz>0.00050234</izz>
          </inertia>
        </inertial>
        <collision name='right_front_wheel_collision'>
          <pose>0 0 0 0 -0 0</pose>
          <geometry>
            <mesh>
              <scale>1 1 1</scale>
              <uri>/home/shivam/catkin_ws2/src/batbat/meshes/right_front_wheel.STL</uri>
            </mesh>
          </geometry>
          <max_contacts>10</max_contacts>
          <surface>
            <contact>
              <ode/>
            </contact>
            <bounce/>
            <friction>
              <torsional>
                <ode/>
              </torsional>
              <ode/>
            </friction>
          </surface>
        </collision>
        <visual name='right_front_wheel_visual'>
          <pose>0 0 0 0 -0 0</pose>
          <geometry>
            <mesh>
              <scale>1 1 1</scale>
              <uri>/home/shivam/catkin_ws2/src/batbat/meshes/right_front_wheel.STL</uri>
            </mesh>
          </geometry>
        </visual>
        <self_collide>0</self_collide>
        <enable_wind>0</enable_wind>
        <kinematic>0</kinematic>
      </link>
      <joint name='right_roll_joint' type='revolute'>
        <pose relative_to='right_front_wheel'>0 -0.038 0.225 -1.5708 -0 3.14159</pose>
        <parent>right_front_wheel</parent>
        <child>right_roll</child>
        <axis>
          <xyz>0 0 -1</xyz>
          <limit>
            <lower>-1e+16</lower>
            <upper>1e+16</upper>
          </limit>
          <dynamics>
            <spring_reference>0</spring_reference>
            <spring_stiffness>0</spring_stiffness>
          </dynamics>
        </axis>
      </joint>
      <link name='right_roll'>
        <pose relative_to='right_roll_joint'>0 0 0 0 -0 0</pose>
        <inertial>
          <pose>0 -0 -0.0385 0 -0 0</pose>
          <mass>0.573287</mass>
          <inertia>
            <ixx>0.00239464</ixx>
            <ixy>1.07472e-18</ixy>
            <ixz>2.45112e-19</ixz>
            <iyy>0.00239464</iyy>
            <iyz>5.10295e-20</iyz>
            <izz>0.00432457</izz>
          </inertia>
        </inertial>
        <collision name='right_roll_collision'>
          <pose>0 0 0 0 -0 0</pose>
          <geometry>
            <mesh>
              <scale>1 1 1</scale>
              <uri>/home/shivam/catkin_ws2/src/batbat/meshes/right_roll.STL</uri>
            </mesh>
          </geometry>
          <max_contacts>10</max_contacts>
          <surface>
            <contact>
              <ode/>
            </contact>
            <bounce/>
            <friction>
              <torsional>
                <ode/>
              </torsional>
              <ode/>
            </friction>
          </surface>
        </collision>
        <visual name='right_roll_visual'>
          <pose>0 0 0 0 -0 0</pose>
          <geometry>
            <mesh>
              <scale>1 1 1</scale>
              <uri>/home/shivam/catkin_ws2/src/batbat/meshes/right_roll.STL</uri>
            </mesh>
          </geometry>
        </visual>
        <self_collide>0</self_collide>
        <enable_wind>0</enable_wind>
        <kinematic>0</kinematic>
      </link>
      <joint name='right_rear_wheel_joint' type='revolute'>
        <pose relative_to='dummy_link'>-0.254 -0.166 0.1015 -1.5708 0 0</pose>
        <parent>dummy_link</parent>
        <child>right_rear_wheel</child>
        <axis>
          <xyz>0 0 1</xyz>
          <limit>
            <lower>-1e+16</lower>
            <upper>1e+16</upper>
          </limit>
          <dynamics>
            <spring_reference>0</spring_reference>
            <spring_stiffness>0</spring_stiffness>
          </dynamics>
        </axis>
      </joint>
      <link name='right_rear_wheel'>
        <pose relative_to='right_rear_wheel_joint'>0 0 0 0 -0 0</pose>
        <inertial>
          <pose>0 0 -0.0385 0 -0 0</pose>
          <mass>0.573287</mass>
          <inertia>
            <ixx>0.00239464</ixx>
            <ixy>1.64596e-20</ixy>
            <ixz>-2.10404e-19</ixz>
            <iyy>0.00239464</iyy>
            <iyz>4.09321e-21</iyz>
            <izz>0.00432457</izz>
          </inertia>
        </inertial>
        <collision name='right_rear_wheel_collision'>
          <pose>0 0 0 0 -0 0</pose>
          <geometry>
            <mesh>
              <scale>1 1 1</scale>
              <uri>/home/shivam/catkin_ws2/src/batbat/meshes/right_rear_wheel.STL</uri>
            </mesh>
          </geometry>
          <max_contacts>10</max_contacts>
          <surface>
            <contact>
              <ode/>
            </contact>
            <bounce/>
            <friction>
              <torsional>
                <ode/>
              </torsional>
              <ode/>
            </friction>
          </surface>
        </collision>
        <visual name='right_rear_wheel_visual'>
          <pose>0 0 0 0 -0 0</pose>
          <geometry>
            <mesh>
              <scale>1 1 1</scale>
              <uri>/home/shivam/catkin_ws2/src/batbat/meshes/right_rear_wheel.STL</uri>
            </mesh>
          </geometry>
        </visual>
        <self_collide>0</self_collide>
        <enable_wind>0</enable_wind>
        <kinematic>0</kinematic>
      </link>
      <plugin name='gazebo_ros_control' filename='libgazebo_ros_control.so'>
        <robotNamespace>/</robotNamespace>
      </plugin>
      <plugin name='gazebo_ros_vacuum_gripper' filename='libgazebo_ros_vacuum_gripper.so'>
        <robotNamespace>/robot/vacuum_gripper</robotNamespace>
        <bodyName>vacuum_effector</bodyName>
        <topicName>grasping</topicName>
      </plugin>
      <static>0</static>
      <plugin name='gazebo_ros_control' filename='libgazebo_ros_control.so'>
        <robotNamespace>/batbat</robotNamespace>
        <robotSimType>gazebo_ros_control/DefaultRobotHWSim</robotSimType>
        <legacyModeNS>1</legacyModeNS>
      </plugin>
      <pose>0 0 0 0 -0 0</pose>
    </model>
    <model name='table_clone'>
      <static>1</static>
      <link name='link'>
        <collision name='surface'>
          <pose>0 0.075 0 0 -0 0</pose>
          <geometry>
            <box>
              <size>2.1 0.8 0.7</size>
            </box>
          </geometry>
          <surface>
            <friction>
              <ode>
                <mu>0.6</mu>
                <mu2>0.6</mu2>
              </ode>
              <torsional>
                <ode/>
              </torsional>
            </friction>
            <contact>
              <ode/>
            </contact>
            <bounce/>
          </surface>
          <max_contacts>10</max_contacts>
        </collision>
        <visual name='visual1'>
          <pose>0 0.075 0 0 -0 0</pose>
          <geometry>
            <box>
              <size>2.1 0.8 0.7</size>
            </box>
          </geometry>
          <material>
            <script>
              <uri>file://media/materials/scripts/gazebo.material</uri>
              <name>Gazebo/Wood</name>
            </script>
          </material>
        </visual>
        <self_collide>0</self_collide>
        <enable_wind>0</enable_wind>
        <kinematic>0</kinematic>
      </link>
      <pose>3.18521 0.717754 0 0 -0 0</pose>
    </model>
    <model name='unit_box_blue_clone'>
      <link name='link'>
        <inertial>
          <mass>0.05</mass>
          <inertia>
            <ixx>5.763e-05</ixx>
            <ixy>0</ixy>
            <ixz>0</ixz>
            <iyy>6.331e-05</iyy>
            <iyz>0</iyz>
            <izz>6.119e-05</izz>
          </inertia>
          <pose>0 0 0 0 -0 0</pose>
        </inertial>
        <self_collide>0</self_collide>
        <enable_wind>0</enable_wind>
        <kinematic>0</kinematic>
        <pose>0 0 0 0 -0 0</pose>
        <gravity>1</gravity>
        <visual name='visual'>
          <geometry>
            <box>
              <size>0.1 0.1 0.0625</size>
            </box>
          </geometry>
          <material>
            <script>
              <name>Gazebo/Grey</name>
              <uri>file://media/materials/scripts/gazebo.material</uri>
            </script>
            <ambient>0 0 1 1</ambient>
            <shader type='vertex'>
              <normal_map>__default__</normal_map>
            </shader>
            <diffuse>0.7 0.7 0.7 1</diffuse>
            <specular>0.01 0.01 0.01 1</specular>
            <emissive>0 0 0 1</emissive>
          </material>
          <pose>0 0 0 0 -0 0</pose>
          <transparency>0</transparency>
          <cast_shadows>1</cast_shadows>
        </visual>
        <collision name='collision'>
          <laser_retro>0</laser_retro>
          <max_contacts>10</max_contacts>
          <pose>0 0 0 0 -0 0</pose>
          <geometry>
            <box>
              <size>0.1 0.1 0.0625</size>
            </box>
          </geometry>
          <surface>
            <friction>
              <ode>
                <mu>5</mu>
                <mu2>5</mu2>
                <fdir1>0 0 0</fdir1>
                <slip1>0</slip1>
                <slip2>0</slip2>
              </ode>
              <torsional>
                <coefficient>1</coefficient>
                <patch_radius>0</patch_radius>
                <surface_radius>0</surface_radius>
                <use_patch_radius>1</use_patch_radius>
                <ode>
                  <slip>0</slip>
                </ode>
              </torsional>
            </friction>
            <bounce>
              <restitution_coefficient>0</restitution_coefficient>
              <threshold>1e+06</threshold>
            </bounce>
            <contact>
              <collide_without_contact>0</collide_without_contact>
              <collide_without_contact_bitmask>1</collide_without_contact_bitmask>
              <collide_bitmask>1</collide_bitmask>
              <ode>
                <soft_cfm>0</soft_cfm>
                <soft_erp>0.2</soft_erp>
                <kp>1e+13</kp>
                <kd>1</kd>
                <max_vel>0.01</max_vel>
                <min_depth>0</min_depth>
              </ode>
              <bullet>
                <split_impulse>1</split_impulse>
                <split_impulse_penetration_threshold>-0.01</split_impulse_penetration_threshold>
                <soft_cfm>0</soft_cfm>
                <soft_erp>0.2</soft_erp>
                <kp>1e+13</kp>
                <kd>1</kd>
              </bullet>
            </contact>
          </surface>
        </collision>
      </link>
      <static>0</static>
      <allow_auto_disable>1</allow_auto_disable>
      <pose>3.29261 0.58342 1.04493 -1e-06 -2e-05 1e-06</pose>
    </model>
    <model name='table_clone_clone'>
      <static>1</static>
      <link name='link'>
        <collision name='surface'>
          <pose>0 0.075 0 0 -0 0</pose>
          <geometry>
            <box>
              <size>2.1 0.8 0.7</size>
            </box>
          </geometry>
          <surface>
            <friction>
              <ode>
                <mu>0.6</mu>
                <mu2>0.6</mu2>
              </ode>
              <torsional>
                <ode/>
              </torsional>
            </friction>
            <contact>
              <ode/>
            </contact>
            <bounce/>
          </surface>
          <max_contacts>10</max_contacts>
        </collision>
        <visual name='visual1'>
          <pose>0 0.075 0 0 -0 0</pose>
          <geometry>
            <box>
              <size>2.1 0.8 0.7</size>
            </box>
          </geometry>
          <material>
            <script>
              <uri>file://media/materials/scripts/gazebo.material</uri>
              <name>Gazebo/Wood</name>
            </script>
          </material>
        </visual>
        <self_collide>0</self_collide>
        <enable_wind>0</enable_wind>
        <kinematic>0</kinematic>
      </link>
      <pose>3.20756 -1.90712 0 0 -0 0</pose>
    </model>
    <model name='table_clone_0'>
      <static>1</static>
      <link name='link'>
        <collision name='surface'>
          <pose>0 0.075 0 0 -0 0</pose>
          <geometry>
            <box>
              <size>2.1 0.8 0.7</size>
            </box>
          </geometry>
          <surface>
            <friction>
              <ode>
                <mu>0.6</mu>
                <mu2>0.6</mu2>
              </ode>
              <torsional>
                <ode/>
              </torsional>
            </friction>
            <contact>
              <ode/>
            </contact>
            <bounce/>
          </surface>
          <max_contacts>10</max_contacts>
        </collision>
        <visual name='visual1'>
          <pose>0 0.075 0 0 -0 0</pose>
          <geometry>
            <box>
              <size>2.1 0.8 0.7</size>
            </box>
          </geometry>
          <material>
            <script>
              <uri>file://media/materials/scripts/gazebo.material</uri>
              <name>Gazebo/Wood</name>
            </script>
          </material>
        </visual>
        <self_collide>0</self_collide>
        <enable_wind>0</enable_wind>
        <kinematic>0</kinematic>
      </link>
      <pose>0.013705 -1.85505 0 0 -0 0</pose>
    </model>
    <model name='unit_box_blue_clone_0'>
      <link name='link'>
        <inertial>
          <mass>0.05</mass>
          <inertia>
            <ixx>5.763e-05</ixx>
            <ixy>0</ixy>
            <ixz>0</ixz>
            <iyy>6.331e-05</iyy>
            <iyz>0</iyz>
            <izz>6.119e-05</izz>
          </inertia>
          <pose>0 0 0 0 -0 0</pose>
        </inertial>
        <self_collide>0</self_collide>
        <enable_wind>0</enable_wind>
        <kinematic>0</kinematic>
        <pose>0 0 0 0 -0 0</pose>
        <gravity>1</gravity>
        <visual name='visual'>
          <geometry>
            <box>
              <size>0.1 0.1 0.0625</size>
            </box>
          </geometry>
          <material>
            <script>
              <name>Gazebo/Grey</name>
              <uri>file://media/materials/scripts/gazebo.material</uri>
            </script>
            <ambient>0 0 1 1</ambient>
            <shader type='vertex'>
              <normal_map>__default__</normal_map>
            </shader>
            <diffuse>0.7 0.7 0.7 1</diffuse>
            <specular>0.01 0.01 0.01 1</specular>
            <emissive>0 0 0 1</emissive>
          </material>
          <pose>0 0 0 0 -0 0</pose>
          <transparency>0</transparency>
          <cast_shadows>1</cast_shadows>
        </visual>
        <collision name='collision'>
          <laser_retro>0</laser_retro>
          <max_contacts>10</max_contacts>
          <pose>0 0 0 0 -0 0</pose>
          <geometry>
            <box>
              <size>0.1 0.1 0.0625</size>
            </box>
          </geometry>
          <surface>
            <friction>
              <ode>
                <mu>5</mu>
                <mu2>5</mu2>
                <fdir1>0 0 0</fdir1>
                <slip1>0</slip1>
                <slip2>0</slip2>
              </ode>
              <torsional>
                <coefficient>1</coefficient>
                <patch_radius>0</patch_radius>
                <surface_radius>0</surface_radius>
                <use_patch_radius>1</use_patch_radius>
                <ode>
                  <slip>0</slip>
                </ode>
              </torsional>
            </friction>
            <bounce>
              <restitution_coefficient>0</restitution_coefficient>
              <threshold>1e+06</threshold>
            </bounce>
            <contact>
              <collide_without_contact>0</collide_without_contact>
              <collide_without_contact_bitmask>1</collide_without_contact_bitmask>
              <collide_bitmask>1</collide_bitmask>
              <ode>
                <soft_cfm>0</soft_cfm>
                <soft_erp>0.2</soft_erp>
                <kp>1e+13</kp>
                <kd>1</kd>
                <max_vel>0.01</max_vel>
                <min_depth>0</min_depth>
              </ode>
              <bullet>
                <split_impulse>1</split_impulse>
                <split_impulse_penetration_threshold>-0.01</split_impulse_penetration_threshold>
                <soft_cfm>0</soft_cfm>
                <soft_erp>0.2</soft_erp>
                <kp>1e+13</kp>
                <kd>1</kd>
              </bullet>
            </contact>
          </surface>
        </collision>
      </link>
      <static>0</static>
      <allow_auto_disable>1</allow_auto_disable>
      <pose>0.437495 -1.75176 0.38125 0 -0 1e-06</pose>
    </model>
    <model name='unit_box_blue_clone_1'>
      <link name='link'>
        <inertial>
          <mass>0.05</mass>
          <inertia>
            <ixx>5.763e-05</ixx>
            <ixy>0</ixy>
            <ixz>0</ixz>
            <iyy>6.331e-05</iyy>
            <iyz>0</iyz>
            <izz>6.119e-05</izz>
          </inertia>
          <pose>0 0 0 0 -0 0</pose>
        </inertial>
        <self_collide>0</self_collide>
        <enable_wind>0</enable_wind>
        <kinematic>0</kinematic>
        <pose>0 0 0 0 -0 0</pose>
        <gravity>1</gravity>
        <visual name='visual'>
          <geometry>
            <box>
              <size>0.1 0.1 0.0625</size>
            </box>
          </geometry>
          <material>
            <script>
              <name>Gazebo/Grey</name>
              <uri>file://media/materials/scripts/gazebo.material</uri>
            </script>
            <ambient>0 0 1 1</ambient>
            <shader type='vertex'>
              <normal_map>__default__</normal_map>
            </shader>
            <diffuse>0.7 0.7 0.7 1</diffuse>
            <specular>0.01 0.01 0.01 1</specular>
            <emissive>0 0 0 1</emissive>
          </material>
          <pose>0 0 0 0 -0 0</pose>
          <transparency>0</transparency>
          <cast_shadows>1</cast_shadows>
        </visual>
        <collision name='collision'>
          <laser_retro>0</laser_retro>
          <max_contacts>10</max_contacts>
          <pose>0 0 0 0 -0 0</pose>
          <geometry>
            <box>
              <size>0.1 0.1 0.0625</size>
            </box>
          </geometry>
          <surface>
            <friction>
              <ode>
                <mu>5</mu>
                <mu2>5</mu2>
                <fdir1>0 0 0</fdir1>
                <slip1>0</slip1>
                <slip2>0</slip2>
              </ode>
              <torsional>
                <coefficient>1</coefficient>
                <patch_radius>0</patch_radius>
                <surface_radius>0</surface_radius>
                <use_patch_radius>1</use_patch_radius>
                <ode>
                  <slip>0</slip>
                </ode>
              </torsional>
            </friction>
            <bounce>
              <restitution_coefficient>0</restitution_coefficient>
              <threshold>1e+06</threshold>
            </bounce>
            <contact>
              <collide_without_contact>0</collide_without_contact>
              <collide_without_contact_bitmask>1</collide_without_contact_bitmask>
              <collide_bitmask>1</collide_bitmask>
              <ode>
                <soft_cfm>0</soft_cfm>
                <soft_erp>0.2</soft_erp>
                <kp>1e+13</kp>
                <kd>1</kd>
                <max_vel>0.01</max_vel>
                <min_depth>0</min_depth>
              </ode>
              <bullet>
                <split_impulse>1</split_impulse>
                <split_impulse_penetration_threshold>-0.01</split_impulse_penetration_threshold>
                <soft_cfm>0</soft_cfm>
                <soft_erp>0.2</soft_erp>
                <kp>1e+13</kp>
                <kd>1</kd>
              </bullet>
            </contact>
          </surface>
        </collision>
      </link>
      <static>0</static>
      <allow_auto_disable>1</allow_auto_disable>
      <pose>3.38684 -1.77494 0.38125 0 -0 1e-06</pose>
    </model>
  </world>
</sdf>
